2023-01-09 15:12:45,901 ERROR: Exception on /api/users/1 [GET] [in /home/anith/Desktop/Djangoproject/flask_microblog/venv/lib/python3.8/site-packages/flask/app.py:1741]
Traceback (most recent call last):
  File "/home/anith/Desktop/Djangoproject/flask_microblog/venv/lib/python3.8/site-packages/flask/app.py", line 2525, in wsgi_app
    response = self.full_dispatch_request()
  File "/home/anith/Desktop/Djangoproject/flask_microblog/venv/lib/python3.8/site-packages/flask/app.py", line 1822, in full_dispatch_request
    rv = self.handle_user_exception(e)
  File "/home/anith/Desktop/Djangoproject/flask_microblog/venv/lib/python3.8/site-packages/flask/app.py", line 1820, in full_dispatch_request
    rv = self.dispatch_request()
  File "/home/anith/Desktop/Djangoproject/flask_microblog/venv/lib/python3.8/site-packages/flask/app.py", line 1796, in dispatch_request
    return self.ensure_sync(self.view_functions[rule.endpoint])(**view_args)
  File "/home/anith/Desktop/Djangoproject/flask_microblog/app/api/users.py", line 7, in get_user
    return jsonify(User.query.get_or_404(id).to-dict())
AttributeError: 'User' object has no attribute 'to'
2023-01-09 15:13:27,974 INFO: Microblog startup [in /home/anith/Desktop/Djangoproject/flask_microblog/app/__init__.py:75]
2023-01-09 15:25:47,707 ERROR: Exception on /api/users [GET] [in /home/anith/Desktop/Djangoproject/flask_microblog/venv/lib/python3.8/site-packages/flask/app.py:1741]
Traceback (most recent call last):
  File "/home/anith/Desktop/Djangoproject/flask_microblog/venv/lib/python3.8/site-packages/flask/app.py", line 2525, in wsgi_app
    response = self.full_dispatch_request()
  File "/home/anith/Desktop/Djangoproject/flask_microblog/venv/lib/python3.8/site-packages/flask/app.py", line 1823, in full_dispatch_request
    return self.finalize_request(rv)
  File "/home/anith/Desktop/Djangoproject/flask_microblog/venv/lib/python3.8/site-packages/flask/app.py", line 1842, in finalize_request
    response = self.make_response(rv)
  File "/home/anith/Desktop/Djangoproject/flask_microblog/venv/lib/python3.8/site-packages/flask/app.py", line 2134, in make_response
    raise TypeError(
TypeError: The view function for 'api.get_users' did not return a valid response. The function either returned None or ended without a return statement.
2023-01-09 15:26:52,037 ERROR: Exception on /api/users [GET] [in /home/anith/Desktop/Djangoproject/flask_microblog/venv/lib/python3.8/site-packages/flask/app.py:1741]
Traceback (most recent call last):
  File "/home/anith/Desktop/Djangoproject/flask_microblog/venv/lib/python3.8/site-packages/flask/app.py", line 2525, in wsgi_app
    response = self.full_dispatch_request()
  File "/home/anith/Desktop/Djangoproject/flask_microblog/venv/lib/python3.8/site-packages/flask/app.py", line 1823, in full_dispatch_request
    return self.finalize_request(rv)
  File "/home/anith/Desktop/Djangoproject/flask_microblog/venv/lib/python3.8/site-packages/flask/app.py", line 1842, in finalize_request
    response = self.make_response(rv)
  File "/home/anith/Desktop/Djangoproject/flask_microblog/venv/lib/python3.8/site-packages/flask/app.py", line 2134, in make_response
    raise TypeError(
TypeError: The view function for 'api.get_users' did not return a valid response. The function either returned None or ended without a return statement.
2023-01-09 15:27:01,073 INFO: Microblog startup [in /home/anith/Desktop/Djangoproject/flask_microblog/app/__init__.py:75]
2023-01-09 15:39:38,684 INFO: Microblog startup [in /home/anith/Desktop/Djangoproject/flask_microblog/app/__init__.py:75]
